2022-06-06 18:42:36,894 INFO    MainThread:142213 [internal.py:wandb_internal():87] W&B internal server running at pid: 142213, started at: 2022-06-06 18:42:36.892860
2022-06-06 18:42:36,895 DEBUG   HandlerThread:142213 [handler.py:handle_request():130] handle_request: check_version
2022-06-06 18:42:36,896 INFO    WriterThread:142213 [datastore.py:open_for_write():77] open: /home/usr1/q70261a/lip2sp_pytorch/wandb/run-20220606_184235-1omsxbj4/run-1omsxbj4.wandb
2022-06-06 18:42:36,898 DEBUG   SenderThread:142213 [sender.py:send():234] send: header
2022-06-06 18:42:36,898 DEBUG   SenderThread:142213 [sender.py:send_request():248] send_request: check_version
2022-06-06 18:42:37,033 DEBUG   SenderThread:142213 [sender.py:send():234] send: run
2022-06-06 18:42:37,241 ERROR   SenderThread:142213 [internal_api.py:execute():144] 401 response executing GraphQL.
2022-06-06 18:42:37,241 ERROR   SenderThread:142213 [internal_api.py:execute():145] {"errors":[{"message":"user is not logged in","path":["upsertBucket"],"extensions":{"code":"PERMISSION_ERROR"}}],"data":{"upsertBucket":null}}
2022-06-06 18:42:38,034 INFO    WriterThread:142213 [datastore.py:close():281] close: /home/usr1/q70261a/lip2sp_pytorch/wandb/run-20220606_184235-1omsxbj4/run-1omsxbj4.wandb
2022-06-06 18:42:38,034 INFO    HandlerThread:142213 [handler.py:finish():731] shutting down handler
2022-06-06 18:42:38,035 ERROR   MainThread:142213 [internal.py:wandb_internal():158] Thread SenderThread:
Traceback (most recent call last):
  File "/home/usr1/q70261a/.pyenv/versions/3.8.10/lib/python3.8/site-packages/wandb/sdk/lib/retry.py", line 102, in __call__
    result = self._call_fn(*args, **kwargs)
  File "/home/usr1/q70261a/.pyenv/versions/3.8.10/lib/python3.8/site-packages/wandb/sdk/internal/internal_api.py", line 147, in execute
    six.reraise(*sys.exc_info())
  File "/home/usr1/q70261a/.pyenv/versions/3.8.10/lib/python3.8/site-packages/six.py", line 719, in reraise
    raise value
  File "/home/usr1/q70261a/.pyenv/versions/3.8.10/lib/python3.8/site-packages/wandb/sdk/internal/internal_api.py", line 141, in execute
    return self.client.execute(*args, **kwargs)
  File "/home/usr1/q70261a/.pyenv/versions/3.8.10/lib/python3.8/site-packages/wandb/vendor/gql-0.2.0/gql/client.py", line 52, in execute
    result = self._get_result(document, *args, **kwargs)
  File "/home/usr1/q70261a/.pyenv/versions/3.8.10/lib/python3.8/site-packages/wandb/vendor/gql-0.2.0/gql/client.py", line 60, in _get_result
    return self.transport.execute(document, *args, **kwargs)
  File "/home/usr1/q70261a/.pyenv/versions/3.8.10/lib/python3.8/site-packages/wandb/vendor/gql-0.2.0/gql/transport/requests.py", line 39, in execute
    request.raise_for_status()
  File "/home/usr1/q70261a/.pyenv/versions/3.8.10/lib/python3.8/site-packages/requests/models.py", line 953, in raise_for_status
    raise HTTPError(http_error_msg, response=self)
requests.exceptions.HTTPError: 401 Client Error: Unauthorized for url: https://api.wandb.ai/graphql

During handling of the above exception, another exception occurred:

Traceback (most recent call last):
  File "/home/usr1/q70261a/.pyenv/versions/3.8.10/lib/python3.8/site-packages/wandb/apis/normalize.py", line 24, in wrapper
    return func(*args, **kwargs)
  File "/home/usr1/q70261a/.pyenv/versions/3.8.10/lib/python3.8/site-packages/wandb/sdk/internal/internal_api.py", line 1298, in upsert_run
    response = self.gql(mutation, variable_values=variable_values, **kwargs)
  File "/home/usr1/q70261a/.pyenv/versions/3.8.10/lib/python3.8/site-packages/wandb/sdk/lib/retry.py", line 118, in __call__
    if not check_retry_fn(e):
  File "/home/usr1/q70261a/.pyenv/versions/3.8.10/lib/python3.8/site-packages/wandb/util.py", line 817, in no_retry_auth
    raise CommError("Invalid or missing api_key.  Run wandb login")
wandb.errors.CommError: Invalid or missing api_key.  Run wandb login

During handling of the above exception, another exception occurred:

Traceback (most recent call last):
  File "/home/usr1/q70261a/.pyenv/versions/3.8.10/lib/python3.8/site-packages/wandb/sdk/internal/internal_util.py", line 52, in run
    self._run()
  File "/home/usr1/q70261a/.pyenv/versions/3.8.10/lib/python3.8/site-packages/wandb/sdk/internal/internal_util.py", line 102, in _run
    self._process(record)
  File "/home/usr1/q70261a/.pyenv/versions/3.8.10/lib/python3.8/site-packages/wandb/sdk/internal/internal.py", line 291, in _process
    self._sm.send(record)
  File "/home/usr1/q70261a/.pyenv/versions/3.8.10/lib/python3.8/site-packages/wandb/sdk/internal/sender.py", line 236, in send
    send_handler(record)
  File "/home/usr1/q70261a/.pyenv/versions/3.8.10/lib/python3.8/site-packages/wandb/sdk/internal/sender.py", line 687, in send_run
    self._init_run(run, config_value_dict)
  File "/home/usr1/q70261a/.pyenv/versions/3.8.10/lib/python3.8/site-packages/wandb/sdk/internal/sender.py", line 711, in _init_run
    server_run, inserted = self._api.upsert_run(
  File "/home/usr1/q70261a/.pyenv/versions/3.8.10/lib/python3.8/site-packages/wandb/apis/normalize.py", line 62, in wrapper
    six.reraise(CommError, CommError(message, err), sys.exc_info()[2])
  File "/home/usr1/q70261a/.pyenv/versions/3.8.10/lib/python3.8/site-packages/six.py", line 718, in reraise
    raise value.with_traceback(tb)
  File "/home/usr1/q70261a/.pyenv/versions/3.8.10/lib/python3.8/site-packages/wandb/apis/normalize.py", line 24, in wrapper
    return func(*args, **kwargs)
  File "/home/usr1/q70261a/.pyenv/versions/3.8.10/lib/python3.8/site-packages/wandb/sdk/internal/internal_api.py", line 1298, in upsert_run
    response = self.gql(mutation, variable_values=variable_values, **kwargs)
  File "/home/usr1/q70261a/.pyenv/versions/3.8.10/lib/python3.8/site-packages/wandb/sdk/lib/retry.py", line 118, in __call__
    if not check_retry_fn(e):
  File "/home/usr1/q70261a/.pyenv/versions/3.8.10/lib/python3.8/site-packages/wandb/util.py", line 817, in no_retry_auth
    raise CommError("Invalid or missing api_key.  Run wandb login")
wandb.errors.CommError: Invalid or missing api_key.  Run wandb login
2022-06-06 18:42:40,163 INFO    MainThread:142213 [internal.py:handle_exit():77] Internal process exited
